Traceback (most recent call last):
  File "/var/home/micha/Documents/Coding/2025/MathMuseums/quick_test.py", line 61, in test_smtp_ssl_auth
    server.login('noreply@math.moshchuk.com', '12345')
    ~~~~~~~~~~~~^^^^^^^^^^^^^^^^^^^^^^^^^^^^^^^^^^^^^^
  File "/usr/lib64/python3.13/smtplib.py", line 750, in login
    raise last_exception
  File "/usr/lib64/python3.13/smtplib.py", line 739, in login
    (code, resp) = self.auth(
                   ~~~~~~~~~^
        authmethod, getattr(self, method_name),
        ^^^^^^^^^^^^^^^^^^^^^^^^^^^^^^^^^^^^^^^
        initial_response_ok=initial_response_ok)
        ^^^^^^^^^^^^^^^^^^^^^^^^^^^^^^^^^^^^^^^^
  File "/usr/lib64/python3.13/smtplib.py", line 662, in auth
    raise SMTPAuthenticationError(code, resp)
smtplib.SMTPAuthenticationError: (535, b'5.7.8 Error: authentication failed: authentication failure')
=== Testing basic connectivity ===
Testing math.moshchuk.com:25... ✗ Failed: timed out
Testing math.moshchuk.com:587... ✗ Failed: [Errno 111] Connection refused
Testing math.moshchuk.com:465... ✓ Connected
Testing mail.math.moshchuk.com:25... ✗ Failed: [Errno -2] Name or service not known
Testing mail.math.moshchuk.com:587... ✗ Failed: [Errno -2] Name or service not known
Testing mail.math.moshchuk.com:465... ✗ Failed: [Errno -2] Name or service not known

=== Testing SMTP connections (no auth) ===
Testing SMTP math.moshchuk.com:25... ✗ Failed: timed out
Testing SMTP math.moshchuk.com:587... ✗ Failed: [Errno 111] Connection refused
Testing SMTP mail.math.moshchuk.com:25... ✗ Failed: [Errno -2] Name or service not known
Testing SMTP mail.math.moshchuk.com:587... ✗ Failed: [Errno -2] Name or service not known

=== Testing SMTP SSL with authentication ===
Testing math.moshchuk.com:465 with SSL auth... ✓ SSL connection established
✗ Failed: (535, b'5.7.8 Error: authentication failed: authentication failure')
